<?xml version="1.0" ?>
<!-- =================================================================================== -->
<!-- |    This document was autogenerated by xacro from robot.urdf.xacro               | -->
<!-- |    EDITING THIS FILE BY HAND IS NOT RECOMMENDED                                 | -->
<!-- =================================================================================== -->
<robot name="hv_bot">
  <material name="black">
    <color rgba="0.0 0.0 0.0 1.0"/>
  </material>
  <material name="blue">
    <color rgba="0.0 0.0 0.8 1.0"/>
  </material>
  <material name="green">
    <color rgba="0.0 0.8 0.0 1.0"/>
  </material>
  <material name="yellow">
    <color rgba="1.0 1.0 0.0 1.0"/>
  </material>
  <material name="dark_grey">
    <color rgba="0.2 0.2 0.2 1.0"/>
  </material>
  <material name="orange">
    <color rgba="1.0 0.4235294117647059 0.0392156862745098 1.0"/>
  </material>
  <material name="brown">
    <color rgba="0.5450980392156862 0.27058823529411763 0.07450980392156863 1.0"/>
  </material>
  <material name="red">
    <color rgba="0.8 0.0 0.0 1.0"/>
  </material>
  <material name="turquoise">
    <color rgba="0.25098039215686274 0.8784313725490196 0.8156862745098039 1.0"/>
  </material>
  <material name="purple">
    <color rgba="0.5019607843137255 0.0 0.5019607843137255 1.0"/>
  </material>
  <material name="white">
    <color rgba="1.0 1.0 1.0 1.0"/>
  </material>
  <material name="aluminium">
    <color rgba="0.5 0.5 0.5 1"/>
  </material>
  <material name="plastic">
    <color rgba="0.1 0.1 0.1 1"/>
  </material>
  <!--................................ INERTIA MATRICES .............................. -->
  <!-- ............................... TROLLEY WHEEL DEFINITION .............................. -->
  <!-- Base -->
  <!--................................ XACRO CONSTANTS .............................. -->
  <!-- ............................... LOAD MACROS ................................. -->
  <!-- ........................... SENSOR PLUGIN ................................... -->
  <gazebo>
    <plugin filename="gz-sim-sensors-system" name="gz::sim::systems::Sensors">
      <render_engine>ogre2</render_engine>
    </plugin>
    <plugin filename="gz-sim-imu-system" name="gz::sim::systems::Imu">
        </plugin>
    <plugin filename="gz-sim-diff-drive-system" name="gz::sim::systems::DiffDrive">
      <left_joint>middle_left_wheel_joint</left_joint>
      <right_joint>middle_right_wheel_joint</right_joint>
      <wheel_separation>0.64</wheel_separation>
      <wheel_radius>0.11</wheel_radius>
      <odom_publish_frequency>30</odom_publish_frequency>
      <topic>/cmd_vel</topic>
      <odom_topic>odom</odom_topic>
      <tf_topic>/tf</tf_topic>
      <frame_id>odom</frame_id>
      <child_frame_id>base_footprint</child_frame_id>
    </plugin>
    <plugin filename="gz-sim-joint-state-publisher-system" name="gz::sim::systems::JointStatePublisher">
      <topic>joint_states</topic>
      <joint_name>middle_left_wheel_joint</joint_name>
      <joint_name>middle_right_wheel_joint</joint_name>
    </plugin>
  </gazebo>
  <gazebo reference="gripper_link">
    <kp>1000000.0</kp>
    <kd>100.0</kd>
    <mu1>15</mu1>
    <mu2>15</mu2>
    <fdir1>1 0 0</fdir1>
    <maxVel>1.0</maxVel>
    <minDepth>0.002</minDepth>
  </gazebo>
  <gazebo>
    <plugin filename="gz-sim-joint-state-publisher-system" name="gz::sim::systems::JointStatePublisher">
      <topic>joint_states</topic>
      <joint_name>shoulder_joint</joint_name>
      <joint_name>upper_arm_joint</joint_name>
      <joint_name>elbow_joint</joint_name>
      <joint_name>lower_arm_joint</joint_name>
      <joint_name>wrist_joint</joint_name>
      <joint_name>gripper_joint</joint_name>
      <joint_name>finger_joint</joint_name>
      <joint_name>base_prismatic_torso</joint_name>
    </plugin>
  </gazebo>
  <gazebo reference="gripper_camera_link">
    <sensor name="camera" type="camera">
      <camera>
        <horizontal_fov>1.3962634</horizontal_fov>
        <image>
          <width>640</width>
          <height>480</height>
          <format>R8G8B8</format>
        </image>
        <clip>
          <near>0.1</near>
          <far>15</far>
        </clip>
        <noise>
          <type>gaussian</type>
          <!-- Noise is sampled independently per pixel on each frame.
               That pixel's noise value is added to each of its color
               channels, which at that point lie in the range [0,1]. -->
          <mean>0.0</mean>
          <stddev>0.007</stddev>
        </noise>
        <optical_frame_id>gripper_camera_link_optical</optical_frame_id>
        <camera_info_topic>gripper_camera/camera_info</camera_info_topic>
      </camera>
      <always_on>1</always_on>
      <update_rate>20</update_rate>
      <visualize>true</visualize>
      <topic>gripper_camera/image</topic>
    </sensor>
  </gazebo>
  <gazebo reference="two_d_lidar">
    <sensor name="gpu_lidar" type="gpu_lidar">
      <topic>scan</topic>
      <update_rate>30</update_rate>
      <gz_frame_id>two_d_lidar</gz_frame_id>
      <lidar>
        <scan>
          <horizontal>
            <samples>361</samples>
            <resolution>1</resolution>
            <min_angle>0.0</min_angle>
            <max_angle>6.283185307179586</max_angle>
          </horizontal>
        </scan>
        <range>
          <min>0.55</min>
          <max>16</max>
          <resolution>0.01</resolution>
        </range>
        <noise>
          <type>gaussian</type>
          <mean>0.0</mean>
          <stddev>0.001</stddev>
        </noise>
      </lidar>
      <always_on>1</always_on>
      <visualize>true</visualize>
    </sensor>
  </gazebo>
  <gazebo reference="imu_link">
    <sensor name="imu" type="imu">
      <always_on>1</always_on>
      <update_rate>50</update_rate>
      <visualize>true</visualize>
      <topic>imu</topic>
      <enable_metrics>true</enable_metrics>
      <gz_frame_id>imu_link</gz_frame_id>
    </sensor>
  </gazebo>
  <!-- ................................ BASE LINK .................................. -->
  <link name="base_footprint"/>
  <link name="base_link"/>
  <joint name="base_joint" type="fixed">
    <parent link="base_footprint"/>
    <child link="base_link"/>
    <origin rpy="0 0 0.0" xyz="0.0 0 0.195"/>
  </joint>
  <link name="chassis_link">
    <collision>
      <origin rpy="0 0 0" xyz="0 0 -0.05"/>
      <geometry>
        <box size="0.9 0.64 0.19"/>
      </geometry>
    </collision>
    <visual>
      <origin rpy="0 0 0" xyz="0 0 -0.205"/>
      <geometry>
        <mesh filename="file:///home/harivathsha/hv_bot/install/hv_bot_arm/share/hv_bot_arm/meshes/bcr_bot_mesh.dae" scale="1 1 1"/>
      </geometry>
    </visual>
    <inertial>
      <mass value="70"/>
      <inertia ixx="2.5999166666666667" ixy="0" ixz="0" iyy="4.935583333333334" iyz="0" izz="7.114333333333334"/>
    </inertial>
  </link>
  <joint name="chassis_joint" type="fixed">
    <parent link="base_link"/>
    <child link="chassis_link"/>
    <origin rpy="0 0 0.0" xyz="0.0 0 0"/>
  </joint>
  <!-- ................................ WHEELS ..................................... -->
  <link name="front_left_wheel">
    <collision>
      <origin rpy="0 1.5707963267948966 1.5707963267948966" xyz="0 0 0"/>
      <geometry>
        <sphere radius="0.06"/>
      </geometry>
    </collision>
    <inertial>
      <origin rpy="0 0 0" xyz="0 0 0"/>
      <mass value="0.1"/>
      <inertia ixx="0.00014399999999999998" ixy="0" ixz="0" iyy="0.00014399999999999998" iyz="0" izz="0.00014399999999999998"/>
    </inertial>
    <mu>0.0</mu>
  </link>
  <joint name="front_left_wheel_joint" type="fixed">
    <parent link="base_link"/>
    <child link="front_left_wheel"/>
    <origin rpy="0 0 0" xyz="0.45 0.27 -0.155"/>
    <axis rpy="0 0 0" xyz="0 1 0"/>
  </joint>
  <gazebo reference="front_left_wheel">
    <material>Gazebo/Black</material>
  </gazebo>
  <link name="front_right_wheel">
    <collision>
      <origin rpy="0 1.5707963267948966 1.5707963267948966" xyz="0 0 0"/>
      <geometry>
        <sphere radius="0.06"/>
      </geometry>
    </collision>
    <inertial>
      <origin rpy="0 0 0" xyz="0 0 0"/>
      <mass value="0.1"/>
      <inertia ixx="0.00014399999999999998" ixy="0" ixz="0" iyy="0.00014399999999999998" iyz="0" izz="0.00014399999999999998"/>
    </inertial>
    <mu>0.0</mu>
  </link>
  <joint name="front_right_wheel_joint" type="fixed">
    <parent link="base_link"/>
    <child link="front_right_wheel"/>
    <origin rpy="0 0 0" xyz="0.45 -0.27 -0.155"/>
    <axis rpy="0 0 0" xyz="0 1 0"/>
  </joint>
  <gazebo reference="front_right_wheel">
    <material>Gazebo/Black</material>
  </gazebo>
  <link name="back_left_wheel">
    <collision>
      <origin rpy="0 1.5707963267948966 1.5707963267948966" xyz="0 0 0"/>
      <geometry>
        <sphere radius="0.06"/>
      </geometry>
    </collision>
    <inertial>
      <origin rpy="0 0 0" xyz="0 0 0"/>
      <mass value="0.1"/>
      <inertia ixx="0.00014399999999999998" ixy="0" ixz="0" iyy="0.00014399999999999998" iyz="0" izz="0.00014399999999999998"/>
    </inertial>
    <mu>0.0</mu>
  </link>
  <joint name="back_left_wheel_joint" type="fixed">
    <parent link="base_link"/>
    <child link="back_left_wheel"/>
    <origin rpy="0 0 0" xyz="-0.45 0.27 -0.155"/>
    <axis rpy="0 0 0" xyz="0 1 0"/>
  </joint>
  <gazebo reference="back_left_wheel">
    <material>Gazebo/Black</material>
  </gazebo>
  <link name="back_right_wheel">
    <collision>
      <origin rpy="0 1.5707963267948966 1.5707963267948966" xyz="0 0 0"/>
      <geometry>
        <sphere radius="0.06"/>
      </geometry>
    </collision>
    <inertial>
      <origin rpy="0 0 0" xyz="0 0 0"/>
      <mass value="0.1"/>
      <inertia ixx="0.00014399999999999998" ixy="0" ixz="0" iyy="0.00014399999999999998" iyz="0" izz="0.00014399999999999998"/>
    </inertial>
    <mu>0.0</mu>
  </link>
  <joint name="back_right_wheel_joint" type="fixed">
    <parent link="base_link"/>
    <child link="back_right_wheel"/>
    <origin rpy="0 0 0" xyz="-0.45 -0.27 -0.155"/>
    <axis rpy="0 0 0" xyz="0 1 0"/>
  </joint>
  <gazebo reference="back_right_wheel">
    <material>Gazebo/Black</material>
  </gazebo>
  <link name="middle_left_wheel">
    <collision>
      <origin rpy="0 1.5707963267948966 1.5707963267948966" xyz="0 0 0"/>
      <geometry>
        <cylinder length="0.05" radius="0.1"/>
      </geometry>
      <self_collide>false</self_collide>
    </collision>
    <inertial>
      <origin rpy="0 1.5707963267948966 1.5707963267948966" xyz="0 0 0"/>
      <mass value="1"/>
      <inertia ixx="0.002708333333333334" ixy="0" ixz="0" iyy="0.002708333333333334" iyz="0" izz="0.005000000000000001"/>
    </inertial>
    <mu>5.0</mu>
  </link>
  <joint name="middle_left_wheel_joint" type="continuous">
    <parent link="base_link"/>
    <child link="middle_left_wheel"/>
    <origin rpy="0 0 0" xyz="0 0.3 -0.11699999999999999"/>
    <axis rpy="0 0 0" xyz="0 1 0"/>
  </joint>
  <gazebo reference="middle_left_wheel">
    <material>Gazebo/Black</material>
  </gazebo>
  <link name="middle_right_wheel">
    <collision>
      <origin rpy="0 1.5707963267948966 1.5707963267948966" xyz="0 0 0"/>
      <geometry>
        <cylinder length="0.05" radius="0.1"/>
      </geometry>
      <self_collide>false</self_collide>
    </collision>
    <inertial>
      <origin rpy="0 1.5707963267948966 1.5707963267948966" xyz="0 0 0"/>
      <mass value="1"/>
      <inertia ixx="0.002708333333333334" ixy="0" ixz="0" iyy="0.002708333333333334" iyz="0" izz="0.005000000000000001"/>
    </inertial>
    <mu>5.0</mu>
  </link>
  <joint name="middle_right_wheel_joint" type="continuous">
    <parent link="base_link"/>
    <child link="middle_right_wheel"/>
    <origin rpy="0 0 0" xyz="0 -0.3 -0.11699999999999999"/>
    <axis rpy="0 0 0" xyz="0 1 0"/>
  </joint>
  <gazebo reference="middle_right_wheel">
    <material>Gazebo/Black</material>
  </gazebo>
  <link name="base_link_torso">
    <inertial>
      <origin rpy="0 1.57 0" xyz="0 0 0"/>
      <mass value="5.0"/>
      <inertia ixx="0.01" ixy="0.0" ixz="0.0" iyy="0.01" iyz="0.0" izz="0.01"/>
    </inertial>
    <visual>
      <origin rpy="0 0 0" xyz="0 0 0"/>
      <geometry>
        <mesh filename="package://hv_bot_arm/meshes/base_link.STL" scale="1000 1000 1000"/>
      </geometry>
      <material name="">
        <color rgba="0.792156862745098 0.819607843137255 0.933333333333333 1"/>
      </material>
    </visual>
    <collision>
      <origin rpy="0 1.57 0" xyz="0 0 0"/>
      <geometry>
        <mesh filename="package://hv_bot_arm/meshes/base_link.STL" scale="1000 1000 1000"/>
      </geometry>
    </collision>
  </link>
  <joint name="torso_joint" type="fixed">
    <parent link="base_link"/>
    <child link="base_link_torso"/>
    <origin rpy="1.57 0 -1.57" xyz="0.0 0 0.145"/>
  </joint>
  <link name="torso_link">
    <visual>
      <geometry>
        <mesh filename="package://hv_bot_arm/meshes/torso.STL" scale="1000 1000 1000"/>
      </geometry>
      <origin rpy="0 0 0.0" xyz="0 0 0"/>
    </visual>
    <collision>
      <geometry>
        <mesh filename="package://hv_bot_arm/meshes/torso.STL" scale="1000 1000 1000"/>
      </geometry>
    </collision>
    <inertial>
      <origin xyz="0.0 0.0 0.0"/>
      <mass value="0.480879"/>
      <inertia ixx="0.222" ixy="0" ixz="0" iyy="0.395" iyz="0" izz="0.222"/>
    </inertial>
  </link>
  <joint name="base_prismatic_torso" type="prismatic">
    <parent link="base_link_torso"/>
    <child link="torso_link"/>
    <axis xyz="0 1 0"/>
    <limit effort="1000.0" lower="0" upper="0.4" velocity="0.5"/>
    <origin rpy="0 0 0" xyz="0 0 0"/>
    <!--pos-->
  </joint>
  <joint name="shoulder_joint" type="revolute">
    <origin rpy="1.57 4.71079637 3.14" xyz="0.0 0.8 0"/>
    <parent link="torso_link"/>
    <child link="shoulder_link"/>
    <limit effort="100" lower="-3.14" upper="3.14" velocity="100"/>
    <dynamics damping="0.1" friction="0.1"/>
    <axis xyz="0 0 1"/>
  </joint>
  <link name="shoulder_link">
    <visual>
      <geometry>
        <mesh filename="package://hv_bot_arm/meshes/DAE/shoulder/shoulder.dae" scale="1.5 1.5 1.5"/>
      </geometry>
    </visual>
    <collision>
      <geometry>
        <mesh filename="package://hv_bot_arm/meshes/STL/shoulder/shoulder.stl" scale="1.5 1.5 1.5"/>
      </geometry>
    </collision>
    <inertial>
      <origin xyz="0.0000223482 0.0000414609 0.0066287000"/>
      <mass value="0.480879"/>
      <inertia ixx="0.222" ixy="0" ixz="0" iyy="0.395" iyz="0" izz="0.222"/>
    </inertial>
    <surface>
      <friction>
        <ode>
          <mu1>1.2</mu1>
          <mu2>1.2</mu2>
          <kp>1e15</kp>
          <kd>1e13</kd>
        </ode>
      </friction>
      <bounce>
        <restitution_coefficient>0.01</restitution_coefficient>
        <threshold>0</threshold>
      </bounce>
      <contact>
        <ode>
          <max_vel>10</max_vel>
        </ode>
      </contact>
    </surface>
  </link>
  <joint name="upper_arm_joint" type="revolute">
    <origin rpy="0 0 0" xyz="0.0 0.005 0.0415"/>
    <parent link="shoulder_link"/>
    <child link="upper_arm_link"/>
    <limit effort="100" lower="-3.14" upper="3.14" velocity="100"/>
    <dynamics damping="0.1" friction="0.1"/>
    <axis xyz="0 1 0"/>
  </joint>
  <link name="upper_arm_link">
    <visual>
      <geometry>
        <mesh filename="package://hv_bot_arm/meshes/DAE/upper_arm/upper_arm.dae" scale="1.5 1.5 1.5"/>
      </geometry>
    </visual>
    <collision>
      <geometry>
        <mesh filename="package://hv_bot_arm/meshes/STL/upper_arm/upper_arm.stl" scale="1.5 1.5 1.5"/>
      </geometry>
    </collision>
    <inertial>
      <origin xyz="0.0 0.0 0.0"/>
      <mass value="0.298"/>
      <inertia ixx="0.002176" ixy="-0.0000030658" ixz="0.0" iyy="0.00005757" iyz="0.0" izz="0.002186"/>
    </inertial>
    <surface>
      <friction>
        <ode>
          <mu1>1.2</mu1>
          <mu2>1.2</mu2>
          <kp>1e15</kp>
          <kd>1e13</kd>
        </ode>
      </friction>
      <bounce>
        <restitution_coefficient>0.01</restitution_coefficient>
        <threshold>0</threshold>
      </bounce>
      <contact>
        <ode>
          <max_vel>10</max_vel>
        </ode>
      </contact>
    </surface>
  </link>
  <joint name="elbow_joint" type="revolute">
    <origin rpy="0 0 0" xyz="0.0 0.0 0.10275"/>
    <parent link="upper_arm_link"/>
    <child link="elbow_link"/>
    <limit effort="100" lower="-3.14" upper="3.14" velocity="100"/>
    <dynamics damping="0.1" friction="0.1"/>
    <axis xyz="1 0 0"/>
  </joint>
  <link name="elbow_link">
    <visual>
      <geometry>
        <mesh filename="package://hv_bot_arm/meshes/DAE/elbow/elbow.dae" scale="1.5 1.5 1.5"/>
      </geometry>
    </visual>
    <collision>
      <geometry>
        <mesh filename="package://hv_bot_arm/meshes/STL/elbow/elbow.stl" scale="1.5 1.5 1.5"/>
      </geometry>
    </collision>
    <inertial>
      <origin xyz="0.1079630000 0.0001158760 0"/>
      <mass value="0.234589"/>
      <inertia ixx="0.00003971" ixy="0.0000023528" ixz="0.0" iyy="0.0008878" iyz="0.0" izz="0.000888"/>
    </inertial>
    <surface>
      <friction>
        <ode>
          <mu1>1.2</mu1>
          <mu2>1.2</mu2>
          <kp>1e15</kp>
          <kd>1e13</kd>
        </ode>
      </friction>
      <bounce>
        <restitution_coefficient>0.01</restitution_coefficient>
        <threshold>0</threshold>
      </bounce>
      <contact>
        <ode>
          <max_vel>10</max_vel>
        </ode>
      </contact>
    </surface>
  </link>
  <joint name="lower_arm_joint" type="revolute">
    <origin rpy="0 -1.3089969750000001 0" xyz="0.0 0.0 0.117"/>
    <parent link="elbow_link"/>
    <child link="lower_arm_link"/>
    <limit effort="100" lower="-3.14" upper="3.14" velocity="100"/>
    <dynamics damping="0.1" friction="0.1"/>
    <axis xyz="0 1 0"/>
  </joint>
  <link name="lower_arm_link">
    <visual>
      <geometry>
        <mesh filename="package://hv_bot_arm/meshes/DAE/lower_arm/lower_arm.dae" scale="1.5 1.5 1.5"/>
      </geometry>
    </visual>
    <collision>
      <geometry>
        <mesh filename="package://hv_bot_arm/meshes/STL/lower_arm/lower_arm.stl" scale="1.5 1.5 1.5"/>
      </geometry>
    </collision>
    <inertial>
      <origin xyz="0.0374395000 0.0052225200 0"/>
      <mass value="0.220991"/>
      <inertia ixx="0.00006369" ixy="-0.00002292" ixz="0.0" iyy="0.0001677" iyz="0.0" izz="0.0001834"/>
    </inertial>
    <surface>
      <friction>
        <ode>
          <mu1>1.2</mu1>
          <mu2>1.2</mu2>
          <kp>1e15</kp>
          <kd>1e13</kd>
        </ode>
      </friction>
      <bounce>
        <restitution_coefficient>0.01</restitution_coefficient>
        <threshold>0</threshold>
      </bounce>
      <contact>
        <ode>
          <max_vel>10</max_vel>
        </ode>
      </contact>
    </surface>
  </link>
  <joint name="wrist_joint" type="revolute">
    <origin rpy="0 -1.832595765 0" xyz="0.0 0.0 0.1245"/>
    <parent link="lower_arm_link"/>
    <child link="wrist_link"/>
    <limit effort="100" lower="-3.14" upper="3.14" velocity="100"/>
    <dynamics damping="0.1" friction="0.1"/>
    <axis xyz="0 1 0"/>
  </joint>
  <link name="wrist_link">
    <visual>
      <geometry>
        <mesh filename="package://hv_bot_arm/meshes/DAE/wrist/wrist.dae" scale="1.5 1.5 1.5"/>
      </geometry>
    </visual>
    <collision>
      <geometry>
        <mesh filename="package://hv_bot_arm/meshes/STL/wrist/wrist.stl" scale="1.5 1.5 1.5"/>
      </geometry>
    </collision>
    <inertial>
      <origin xyz="0.0 0.0 0.0"/>
      <mass value="0.085"/>
      <inertia ixx="0.00003082" ixy="0.0000000191" ixz="0.0000000023" iyy="0.00002822" iyz="0.0000025481" izz="0.00003152"/>
    </inertial>
    <surface>
      <friction>
        <ode>
          <mu1>1.2</mu1>
          <mu2>1.2</mu2>
          <kp>1e15</kp>
          <kd>1e13</kd>
        </ode>
      </friction>
      <bounce>
        <restitution_coefficient>0.01</restitution_coefficient>
        <threshold>0</threshold>
        <origin rpy="-0.52359879 0 0" xyz="0.0 0.01475 -0.037"/>
      </bounce>
      <contact>
        <ode>
          <max_vel>10</max_vel>
        </ode>
      </contact>
    </surface>
  </link>
  <joint name="gripper_joint" type="revolute">
    <origin rpy="0 0 0" xyz="0.0 0.0 0.183"/>
    <parent link="wrist_link"/>
    <child link="gripper_link"/>
    <limit effort="100" lower="-3.14" upper="3.14" velocity="100"/>
    <dynamics damping="0.1" friction="0.1"/>
    <axis xyz="0 0 1"/>
  </joint>
  <link name="gripper_link">
    <visual>
      <geometry>
        <mesh filename="package://hv_bot_arm/meshes/DAE/gripper/gripper.dae" scale="1.5 1.5 1.5"/>
      </geometry>
    </visual>
    <collision>
      <geometry>
        <mesh filename="package://hv_bot_arm/meshes/STL/gripper/gripper.stl" scale="1.5 1.5 1.5"/>
      </geometry>
    </collision>
    <inertial>
      <origin xyz="0.0 0.0 0.0"/>
      <mass value="0.25"/>
      <inertia ixx="0.00002537" ixy="0.0" ixz="0.0" iyy="0.00001836" iyz="0.000000434" izz="0.00001674"/>
    </inertial>
    <surface>
      <friction>
        <ode>
          <mu1>1.2</mu1>
          <mu2>1.2</mu2>
          <kp>1e15</kp>
          <kd>1e13</kd>
        </ode>
      </friction>
      <bounce>
        <restitution_coefficient>0.01</restitution_coefficient>
        <threshold>0</threshold>
      </bounce>
      <contact>
        <ode>
          <max_vel>10</max_vel>
        </ode>
      </contact>
    </surface>
  </link>
  <gazebo reference="gripper_link">
    <mu1>1.2</mu1>
    <mu2>1.2</mu2>
    <kp>1e15</kp>
    <kd>1e13</kd>
    <fdir1>1 0 0</fdir1>
    <maxVel>1.0</maxVel>
    <minDepth>0.002</minDepth>
  </gazebo>
  <joint name="finger_joint" type="revolute">
    <origin rpy="-0.52359879 0 0" xyz="0.0 0.022125 -0.0555"/>
    <parent link="gripper_link"/>
    <child link="finger_link"/>
    <limit effort="100" lower="-1.57" upper="1.57" velocity="100"/>
    <dynamics damping="0.005" friction="0.039"/>
    <axis xyz="1 0 0"/>
  </joint>
  <link name="finger_link">
    <visual>
      <geometry>
        <mesh filename="package://hv_bot_arm/meshes/DAE/finger/finger.dae" scale="1.5 1.5 1.5"/>
      </geometry>
    </visual>
    <collision>
      <geometry>
        <mesh filename="package://hv_bot_arm/meshes/STL/finger/finger.stl" scale="1.5 1.5 1.5"/>
      </geometry>
    </collision>
    <inertial>
      <origin xyz="0.0 0.0 0.0"/>
      <mass value="0.016"/>
      <inertia ixx="0.00009" ixy="0.0" ixz="0.0" iyy="0.00009" iyz="0.0" izz="0.00002"/>
    </inertial>
    <origin rpy="-0.52359879 0 0" xyz="0.0 0.01475 -0.037"/>
    <surface>
      <friction>
        <ode>
          <mu1>1.2</mu1>
          <mu2>1.2</mu2>
          <kp>1e15</kp>
          <kd>1e13</kd>
        </ode>
      </friction>
      <bounce>
        <restitution_coefficient>0.01</restitution_coefficient>
        <threshold>0</threshold>
      </bounce>
      <contact>
        <ode>
          <max_vel>10</max_vel>
        </ode>
      </contact>
    </surface>
  </link>
  <gazebo reference="finger_link">
    <mu1>1.2</mu1>
    <mu2>1.2</mu2>
    <kp>1e15</kp>
    <kd>1e13</kd>
    <fdir1>1 0 0</fdir1>
    <maxVel>1.0</maxVel>
    <minDepth>0.002</minDepth>
  </gazebo>
  <!-- STEP 11 - Gripper camera -->
  <joint name="gripper_camera_joint" type="fixed">
    <origin rpy="0 -1.5707 0" xyz="0.0 0.0 0.0"/>
    <child link="gripper_camera_link"/>
    <parent link="gripper_link"/>
  </joint>
  <link name="gripper_camera_link">
    <pose>0 0 0 0 0 0</pose>
    <inertial>
      <mass value="1.0e-03"/>
      <origin rpy="0 0 0" xyz="0 0 0"/>
      <inertia ixx="1e-6" ixy="0" ixz="0" iyy="1e-6" iyz="0" izz="1e-6"/>
    </inertial>
    <visual>
      <origin rpy="0 0 0" xyz="0 0 0"/>
      <geometry>
        <box size=".01 .01 .01"/>
      </geometry>
      <material name="red"/>
    </visual>
  </link>
  <joint name="gripper_camera_optical_joint" type="fixed">
    <origin rpy="-1.5707 0 -1.5707" xyz="0 0 0"/>
    <child link="gripper_camera_link_optical"/>
    <parent link="gripper_camera_link"/>
  </joint>
  <link name="gripper_camera_link_optical">
  </link>
  <joint name="imu_joint" type="fixed">
    <origin rpy="0 0 0" xyz="0 0 0"/>
    <parent link="base_link"/>
    <child link="imu_link"/>
  </joint>
  <link name="imu_link">
  </link>
  <ros2_control name="GazeboSystem" type="system">
    <hardware>
      <plugin>gz_ros2_control/GazeboSimSystem</plugin>
    </hardware>
    <joint name="base_prismatic_torso">
      <command_interface name="position">
        <param name="min">-2</param>
        <param name="max">2</param>
      </command_interface>
      <state_interface name="position">
        <param name="initial_value">0.0</param>
      </state_interface>
      <state_interface name="velocity"/>
      <state_interface name="effort"/>
    </joint>
    <joint name="shoulder_joint">
      <command_interface name="position">
        <param name="min">-2</param>
        <param name="max">2</param>
      </command_interface>
      <state_interface name="position">
        <param name="initial_value">0.0</param>
      </state_interface>
      <state_interface name="velocity"/>
      <state_interface name="effort"/>
    </joint>
    <joint name="upper_arm_joint">
      <command_interface name="position">
        <param name="min">-2</param>
        <param name="max">2</param>
      </command_interface>
      <state_interface name="position">
        <param name="initial_value">0.0</param>
      </state_interface>
      <state_interface name="velocity"/>
      <state_interface name="effort"/>
    </joint>
    <joint name="elbow_joint">
      <command_interface name="position">
        <param name="min">-2</param>
        <param name="max">2</param>
      </command_interface>
      <state_interface name="position">
        <param name="initial_value">0.0</param>
      </state_interface>
      <state_interface name="velocity"/>
      <state_interface name="effort"/>
    </joint>
    <joint name="lower_arm_joint">
      <command_interface name="position">
        <param name="min">-2</param>
        <param name="max">2</param>
      </command_interface>
      <state_interface name="position">
        <param name="initial_value">0.0</param>
      </state_interface>
      <state_interface name="velocity"/>
      <state_interface name="effort"/>
    </joint>
    <joint name="wrist_joint">
      <command_interface name="position">
        <param name="min">-2</param>
        <param name="max">2</param>
      </command_interface>
      <state_interface name="position">
        <param name="initial_value">0.0</param>
      </state_interface>
      <state_interface name="velocity"/>
      <state_interface name="effort"/>
    </joint>
    <joint name="gripper_joint">
      <command_interface name="position">
        <param name="min">-2</param>
        <param name="max">2</param>
      </command_interface>
      <state_interface name="position">
        <param name="initial_value">0.0</param>
      </state_interface>
      <state_interface name="velocity"/>
      <state_interface name="effort"/>
    </joint>
    <joint name="finger_joint">
      <command_interface name="position">
        <param name="min">-2</param>
        <param name="max">2</param>
      </command_interface>
      <state_interface name="position">
        <param name="initial_value">0.0</param>
      </state_interface>
      <state_interface name="velocity"/>
      <state_interface name="effort"/>
    </joint>
  </ros2_control>
  <gazebo>
    <plugin filename="libgz_ros2_control-system.so" name="gz_ros2_control::GazeboSimROS2ControlPlugin">
      <parameters>/home/harivathsha/hv_bot/install/hv_bot_arm/share/hv_bot_arm/config/my_controllers.yaml</parameters>
      <parameters>/home/harivathsha/hv_bot/install/hv_bot_arm/share/hv_bot_arm/config/gaz_ros2_ctl_use_sim.yaml</parameters>
    </plugin>
  </gazebo>
  <link name="two_d_lidar">
    <collision>
      <origin rpy="0 0 0" xyz="0 0 0"/>
      <geometry>
        <cylinder length="0.06" radius="0.075"/>
      </geometry>
    </collision>
    <visual>
      <origin rpy="0 0 0" xyz="0 0 0"/>
      <geometry>
        <cylinder length="0.06" radius="0.075"/>
      </geometry>
      <material name="aluminium"/>
    </visual>
    <inertial>
      <origin rpy="0 0 0" xyz="0 0 0"/>
      <mass value="0.1"/>
      <inertia ixx="0.000170625" ixy="0" ixz="0" iyy="0.000170625" iyz="0" izz="0.00028125"/>
    </inertial>
  </link>
  <joint name="two_d_lidar_joint" type="fixed">
    <parent link="base_link"/>
    <child link="two_d_lidar"/>
    <origin rpy="0 0 0" xyz="0.0 0 0.08"/>
  </joint>
  <gazebo reference="two_d_lidar">
    <material>Gazebo/White</material>
  </gazebo>
  <!-- STEREO CAMERA -->
  <link name="stereo_camera">
    <collision>
      <origin rpy="0 0 0" xyz="0 0 0"/>
      <geometry>
        <box size="0.07 0.3 0.09"/>
      </geometry>
    </collision>
    <visual>
      <origin rpy="0 0 0" xyz="0 0 0"/>
      <geometry>
        <mesh filename="file:///home/harivathsha/hv_bot/install/hv_bot_arm/share/hv_bot_arm/meshes/kinect/d415.dae"/>
      </geometry>
      <material name="black"/>
    </visual>
    <inertial>
      <mass value="0.01"/>
      <inertia ixx="8.175e-05" ixy="0" ixz="0" iyy="1.0833333333333335e-05" iyz="0" izz="7.908333333333334e-05"/>
    </inertial>
  </link>
  <joint name="stereo_camera_joint" type="fixed">
    <origin rpy="0 0 0" xyz="0.45 0 0.027142857142857142"/>
    <parent link="base_link"/>
    <child link="stereo_camera"/>
  </joint>
  <link name="stereo_camera_optical"/>
  <joint name="stereo_camera_optical_joint" type="fixed">
    <origin rpy="-1.5707963267948966 0 -1.5707963267948966" xyz="0 0 0"/>
    <parent link="stereo_camera"/>
    <child link="stereo_camera_optical"/>
  </joint>
  <gazebo reference="stereo_camera">
    <sensor name="right" type="camera">
      <update_rate>10.0</update_rate>
      <always_on>true</always_on>
      <gz_frame_id>stereo_camera_optical</gz_frame_id>
      <pose>0 -0.12 0 0 0 0</pose>
      <topic>stereo_camera/right/image_raw</topic>
      <camera_info_topic>stereo_camera/right/camera_info</camera_info_topic>
      <horizontal_fov>1.3962634</horizontal_fov>
      <image>
        <width>1024</width>
        <height>1024</height>
        <format>R8G8B8</format>
      </image>
      <clip>
        <near>0.3</near>
        <far>20</far>
      </clip>
    </sensor>
    <sensor name="left" type="camera">
      <topic>stereo_camera/left/image_raw</topic>
      <update_rate>10.0</update_rate>
      <always_on>true</always_on>
      <gz_frame_id>stereo_camera_optical</gz_frame_id>
      <camera_info_topic>stereo_camera/left/camera_info</camera_info_topic>
      <pose>0 0 0 0 0 0</pose>
      <horizontal_fov>1.3962634</horizontal_fov>
      <image>
        <width>1024</width>
        <height>1024</height>
        <format>R8G8B8</format>
      </image>
      <clip>
        <near>0.3</near>
        <far>20</far>
      </clip>
    </sensor>
  </gazebo>
  <link name="kinect_camera">
    <collision>
      <origin rpy="0 0 0" xyz="0 0 0"/>
      <geometry>
        <box size="0.07 0.3 0.09"/>
      </geometry>
    </collision>
    <visual>
      <origin rpy="0 0 0" xyz="0 0 0"/>
      <geometry>
        <mesh filename="file:///home/harivathsha/hv_bot/install/hv_bot_arm/share/hv_bot_arm/meshes/kinect/d415.dae"/>
      </geometry>
      <material name="black"/>
    </visual>
    <inertial>
      <mass value="0.01"/>
      <inertia ixx="8.175e-05" ixy="0" ixz="0" iyy="1.0833333333333335e-05" iyz="0" izz="7.908333333333334e-05"/>
    </inertial>
  </link>
  <joint name="kinect_camera_joint" type="fixed">
    <origin rpy="0 0 0" xyz="0.45 0 0.027142857142857142"/>
    <parent link="base_link"/>
    <child link="kinect_camera"/>
  </joint>
  <link name="kinect_camera_optical"/>
  <joint name="kinect_camera_optical_joint" type="fixed">
    <origin rpy="-1.5707963267948966 0 -1.5707963267948966" xyz="0 0 0"/>
    <parent link="kinect_camera"/>
    <child link="kinect_camera_optical"/>
  </joint>
  <gazebo reference="kinect_camera">
    <sensor name="kinect_camera" type="depth_camera">
      <update_rate>30.0</update_rate>
      <topic>kinect_camera</topic>
      <gz_frame_id>kinect_camera</gz_frame_id>
      <camera>
        <camera_info_topic>kinect_camera/camera_info</camera_info_topic>
        <horizontal_fov>1.0471975511965976</horizontal_fov>
        <image>
          <width>640</width>
          <height>480</height>
          <format>R8G8B8</format>
        </image>
        <clip>
          <near>0.05</near>
          <far>8.0</far>
        </clip>
      </camera>
    </sensor>
  </gazebo>
</robot>
